<?xml version="1.0"?>
<robot name="my_robot" xmlns:xacro="http://www.ros.org/wiki/xacro">
  <!-- more description -->

<xacro:include filename="$(find my_robot)/urdf/my_robot.gazebo.xacro"/>
<xacro:arg name="gpu" default="false"/>
<xacro:property name="gpu" value="$(arg gpu)" />


    <link name="base_footprint"/>

    <joint name="base_joint" type="fixed">
        <parent link="base_footprint"/>
        <child link="robot_base_link"/>
        <origin xyz="0.0 0.0 0.00" rpy="0 0 0"/>
    </joint>

    <link name="robot_base_link">
        <inertial>
            <mass value="100"/>
            <inertia ixx="100"  ixy="0"  ixz="0" iyy="100" iyz="0" izz="100" />
        </inertial>
        <collision>
            <geometry>
            <box size="0.4 0.2 0.1"/>   <!-- x y z -->
            </geometry>
        </collision>
        <visual>
            <geometry>
            <box size="0.4 0.2 0.1"/>   <!-- x y z -->
            </geometry>
        </visual>
        
    </link>

    <link name="platform">
        <inertial>
            <mass value="3"/>
            <inertia ixx="50"  ixy="0"  ixz="0" iyy="50" iyz="0" izz="50" />
        </inertial>
        <collision>
            <geometry>
            <cylinder length="0.1" radius="0.08"/>
            </geometry>
        </collision>
        <visual>
            <geometry>
            <cylinder length="0.1" radius="0.08"/>
            </geometry>
        </visual>
    </link>

    <joint name="platform_joint" type="fixed">
        <parent link="robot_base_link"/>
        <child link="platform"/>
        <origin xyz="0.0 0.0 0.1" rpy="0 0 0"/>
    </joint>

    <link name="left_front_wheel">
        <inertial>
            <origin xyz="0 0 0" rpy="0 0 0"/>
            <mass value="3"/>
            <inertia ixx="10"  ixy="0"  ixz="0" iyy="10" iyz="0" izz="10" />
        </inertial>
        <collision>
        <origin xyz="0 0 0" rpy="0 1.5707 1.5707"/>
            <geometry>
            <cylinder length="0.05" radius="0.1"/>
            </geometry>
        </collision>
        <visual>
        <origin xyz="0 0 0" rpy="0 1.5707 1.5707"/>
            <geometry>
            <cylinder length="0.05" radius="0.1"/>
            </geometry>
        </visual>
    </link>



    <link name="right_front_wheel">
        <collision>
            <origin xyz="0 0 0" rpy="0 1.5707 1.5707"/>
            <geometry>
            <cylinder length="0.05" radius="0.1"/>
            </geometry>
        </collision>
        <visual>
            <origin xyz="0 0 0" rpy="0 1.5707 1.5707"/>
            <geometry>
            <cylinder length="0.05" radius="0.1"/>
            </geometry>
        </visual>
        <inertial>
            <origin xyz="0 0 0" rpy="0 0 0"/>
            <mass value="3"/>
            <inertia ixx="10"  ixy="0"  ixz="0" iyy="10" iyz="0" izz="10" />
        </inertial>
        </link>

    <link name="left_back_wheel">
        <inertial>
            <origin xyz="0 0 0" rpy="0 0 0"/>
            <mass value="10"/>
            <inertia ixx="10"  ixy="0"  ixz="0" iyy="10" iyz="0" izz="100" />
        </inertial>
        <collision>
        <origin xyz="0 0 0" rpy="0 1.5707 1.5707"/>
            <geometry>
            <cylinder length="0.05" radius="0.1"/>
            </geometry>
        </collision>
        <visual>
        <origin xyz="0 0 0" rpy="0 1.5707 1.5707"/>
            <geometry>
            <cylinder length="0.05" radius="0.1"/>
            </geometry>
        </visual>
    </link>



    <link name="right_back_wheel">
        <collision>
            <origin xyz="0 0 0" rpy="0 1.5707 1.5707"/>
            <geometry>
            <cylinder length="0.05" radius="0.1"/>
            </geometry>
        </collision>
        <visual>
            <origin xyz="0 0 0" rpy="0 1.5707 1.5707"/>
            <geometry>
            <cylinder length="0.05" radius="0.1"/>
            </geometry>
        </visual>
        <inertial>
            <origin xyz="0 0 0" rpy="0 0 0"/>
            <mass value="3"/>
            <inertia ixx="10"  ixy="0"  ixz="0" iyy="10" iyz="0" izz="10" />
        </inertial>
    </link>


    <joint type="continuous" name="left_front_hinge">
        <origin xyz="0.13 0.13 0" rpy="0 0 0"/>
        <child link="left_front_wheel"/>
        <parent link="robot_base_link"/>
        <axis xyz="0 1 0"/>
    </joint>

    <joint type="continuous" name="right_front_hinge">
        <origin xyz="0.13 -0.13 0" rpy="0 0 0"/>
        <child link="right_front_wheel"/>
        <parent link="robot_base_link"/>
        <axis xyz="0 1 0"/>
    </joint>

    <joint type="continuous" name="left_back_hinge">
        <origin xyz="-0.13 0.13 0" rpy="0 0 0"/>
        <child link="left_back_wheel"/>
        <parent link="robot_base_link"/>
        <axis xyz="0 1 0"/>
    </joint>

    <joint type="continuous" name="right_back_hinge">
        <origin xyz="-0.13 -0.13 0" rpy="0 0 0"/>
        <child link="right_back_wheel"/>
        <parent link="robot_base_link"/>
        <axis xyz="0 1 0"/>
    </joint>


    <link name="imu_link"/>

    <joint name="imu_joint" type="fixed">
        <parent link="robot_base_link"/>
        <child link="imu_link"/>
        <origin xyz="-0.032 0 0.172" rpy="0 0 0"/>
    </joint>

     <!-- <xacro:include filename="$(find velodyne_description)/urdf/VLP-16.urdf.xacro"/>
    <VLP-16 parent="robot_base_link" name="velodyne" topic="/velodyne_points" hz="10" samples="1800" gpu="${gpu}">
        <origin xyz="0 0 0.15" rpy="0 0 0" />
    </VLP-16> -->


    <gazebo>
        <plugin name="gazebo_ros_control" filename="libgazebo_ros_control.so">
        <robotNamespace>/</robotNamespace>
        </plugin>
    </gazebo>

</robot>
